Workbook
Name complementoSKU: #REF!
Name maezert: [1]Zert!$A$3:$G$145
Name motivo: '[2]Mot Mvmtos'!$A$3:$F$180
Name planta: [1]Mae_centros!$H$3:$M$90

Sheet Productos
A1: =COUNTA(A3:A65001) -> 1233 | B1: Texto breve de material
A2: 88 | B2: SEPARADOR PLASTICO
A3: 50166 | B3: FANTA NARANJA 200 ML PET (24)
A4: 50152 | B4: 8PACK FRESH NARANJA 250 ML PET (24)
A5: 50034 | B5: AGUA BRISA BIDON 6 LT (2)
A6: 50109 | B6: 2PACK POWERADE (MANZ + MB)
A7: 50145 | B7: 6 PACK FRESH TETRASURT (LONCHERA-FESTIVAL)
A8: 50142 | B8: 3PACKPOWERADE (MANZ+MB+FT)+ITEM
A9: 50173 | B9: 3 PACK 2 CC 2,5 GRATIS FANTA NARANJA
A10: 50189 | B10: 2PACK COCA-COLA 2,5L GRTS BANDEJA
A11: 50180 | B11: P4LL6 Tetra 200ml Surtido (2NAR + 2LIM + 2 MANZ)
A12: 50181 | B12: P8LL12 Tetra 200ml Surtido (FRESH)
A14: 50279 | B14: COCA COLA 500 ML PET (12)
... A1236: 50391 | B1236: PREMIO ROJO 500ML (12)

Sheet Datos
A2: INVENTARIO PISO
A4: Locación: | B4: Fecha: | C4: 43165
A5: Producto | B5: Descripción | D5: Cantidad
D361: 0
D362: 0
D363: 0
D364: 0
D365: 0
D366: 0
D367: 0
D368: 0
D369: 0
D370: 0
D371: 0
D372: 0
... D428: 0
B429: =IF(ISERROR(VLOOKUP(A429,Productos!$A$3:$B$1232,2,0)),"",VLOOKUP(A429,Productos!$A$3:$B$1232,2,0))
B430: =IF(ISERROR(VLOOKUP(A430,Productos!$A$3:$B$1232,2,0)),"",VLOOKUP(A430,Productos!$A$3:$B$1232,2,0))
B431: =IF(ISERROR(VLOOKUP(A431,Productos!$A$3:$B$1232,2,0)),"",VLOOKUP(A431,Productos!$A$3:$B$1232,2,0))
B432: =IF(ISERROR(VLOOKUP(A432,Productos!$A$3:$B$1232,2,0)),"",VLOOKUP(A432,Productos!$A$3:$B$1232,2,0))
B433: =IF(ISERROR(VLOOKUP(A433,Productos!$A$3:$B$1232,2,0)),"",VLOOKUP(A433,Productos!$A$3:$B$1232,2,0))
B434: =IF(ISERROR(VLOOKUP(A434,Productos!$A$3:$B$1232,2,0)),"",VLOOKUP(A434,Productos!$A$3:$B$1232,2,0))
B435: =IF(ISERROR(VLOOKUP(A435,Productos!$A$3:$B$1232,2,0)),"",VLOOKUP(A435,Productos!$A$3:$B$1232,2,0))
B436: =IF(ISERROR(VLOOKUP(A436,Productos!$A$3:$B$1232,2,0)),"",VLOOKUP(A436,Productos!$A$3:$B$1232,2,0))
B437: =IF(ISERROR(VLOOKUP(A437,Productos!$A$3:$B$1232,2,0)),"",VLOOKUP(A437,Productos!$A$3:$B$1232,2,0))
B438: =IF(ISERROR(VLOOKUP(A438,Productos!$A$3:$B$1232,2,0)),"",VLOOKUP(A438,Productos!$A$3:$B$1232,2,0))
B439: =IF(ISERROR(VLOOKUP(A439,Productos!$A$3:$B$1232,2,0)),"",VLOOKUP(A439,Productos!$A$3:$B$1232,2,0))
B440: =IF(ISERROR(VLOOKUP(A440,Productos!$A$3:$B$1232,2,0)),"",VLOOKUP(A440,Productos!$A$3:$B$1232,2,0))
... B501: =IF(ISERROR(VLOOKUP(A501,Productos!$A$3:$B$1232,2,0)),"",VLOOKUP(A501,Productos!$A$3:$B$1232,2,0))
B502: =IF(ISERROR(VLOOKUP(A502,Productos!$A$3:$B$1229,2,0)),"",VLOOKUP(A502,Productos!$A$3:$B$1229,2,0))
B503: =IF(ISERROR(VLOOKUP(A503,Productos!$A$3:$B$1229,2,0)),"",VLOOKUP(A503,Productos!$A$3:$B$1229,2,0))
B504: =IF(ISERROR(VLOOKUP(A504,Productos!$A$3:$B$1229,2,0)),"",VLOOKUP(A504,Productos!$A$3:$B$1229,2,0))
B505: =IF(ISERROR(VLOOKUP(A505,Productos!$A$3:$B$1229,2,0)),"",VLOOKUP(A505,Productos!$A$3:$B$1229,2,0))
B506: =IF(ISERROR(VLOOKUP(A506,Productos!$A$3:$B$1229,2,0)),"",VLOOKUP(A506,Productos!$A$3:$B$1229,2,0))
B507: =IF(ISERROR(VLOOKUP(A507,Productos!$A$3:$B$1229,2,0)),"",VLOOKUP(A507,Productos!$A$3:$B$1229,2,0))
B508: =IF(ISERROR(VLOOKUP(A508,Productos!$A$3:$B$1229,2,0)),"",VLOOKUP(A508,Productos!$A$3:$B$1229,2,0))
B509: =IF(ISERROR(VLOOKUP(A509,Productos!$A$3:$B$1229,2,0)),"",VLOOKUP(A509,Productos!$A$3:$B$1229,2,0))
B510: =IF(ISERROR(VLOOKUP(A510,Productos!$A$3:$B$1229,2,0)),"",VLOOKUP(A510,Productos!$A$3:$B$1229,2,0))
B511: =IF(ISERROR(VLOOKUP(A511,Productos!$A$3:$B$1229,2,0)),"",VLOOKUP(A511,Productos!$A$3:$B$1229,2,0))
B512: =IF(ISERROR(VLOOKUP(A512,Productos!$A$3:$B$1229,2,0)),"",VLOOKUP(A512,Productos!$A$3:$B$1229,2,0))
...

Sheet Hoja2
B6: codigo | C6: descripcion | D6: cantidad
B7: 136415 | C7: COCA COLA 500ML PET(12) | D7: 1416
B8: 160318 | C8: COCA-COLA 400ML PET (12) | D8: 3658.7

Sheet Locaciones
A1: =COUNTA(A3:A65000) -> 38
A2: CODIGO | B2: LOCACION
A3: 47 | B3: Aguachica
A4: 30 | B4: Armenia
A5: 40 | B5: Barbosa
A6: 50 | B6: Barrancabermeja
A7: 52 | B7: Barranquilla
A8: 20 | B8: Bogota Norte
A9: 22 | B9: Bogota Sur
A10: 45 | B10: Bucaramanga
A11: 26 | B11: Buenaventura
A12: 25 | B12: Buga
A13: 24 | B13: Cali
A14: 54 | B14: Cartagena
... A40: 38 | B40: Yopal
